Starting rankings update...
Fetching current season...
Updating MoneyRankings for season 2025...

[1/1] Processing MoneyRankings...
Fetching MoneyRankings data from API...
Fetched 129 MoneyRankings records
Saving MoneyRankings to database...
Failed to update MoneyRankings: duplicate key value violates unique constraint "oneFourSeven_ranking_Player_id_Season_Type_cdead264_uniq"
DETAIL:  Key ("Player_id", "Season", "Type")=(12, 2025, MoneyRankings) already exists.

Error updating MoneyRankings: duplicate key value violates unique constraint "oneFourSeven_ranking_Player_id_Season_Type_cdead264_uniq"
DETAIL:  Key ("Player_id", "Season", "Type")=(12, 2025, MoneyRankings) already exists.
Traceback (most recent call last):
  File "C:\Users\Aviel\vsprojects\snookerApp\venv\Lib\site-packages\django\db\backends\utils.py", line 105, in _execute  
    return self.cursor.execute(sql, params)
           ^^^^^^^^^^^^^^^^^^^^^^^^^^^^^^^^
psycopg2.errors.UniqueViolation: duplicate key value violates unique constraint "oneFourSeven_ranking_Player_id_Season_Type_cdead264_uniq"
DETAIL:  Key ("Player_id", "Season", "Type")=(12, 2025, MoneyRankings) already exists.


The above exception was the direct cause of the following exception:

Traceback (most recent call last):
  File "C:\Users\Aviel\vsprojects\snookerApp\maxbreak\oneFourSeven\management\commands\update_rankings.py", line 122, in handle
    save_rankings(rankings_data)
  File "C:\Users\Aviel\vsprojects\snookerApp\maxbreak\oneFourSeven\data_savers.py", line 272, in save_rankings
    existing_by_logical_key.save()
  File "C:\Users\Aviel\vsprojects\snookerApp\venv\Lib\site-packages\django\db\models\base.py", line 892, in save
    self.save_base(
  File "C:\Users\Aviel\vsprojects\snookerApp\venv\Lib\site-packages\django\db\models\base.py", line 998, in save_base    
    updated = self._save_table(
              ^^^^^^^^^^^^^^^^^
  File "C:\Users\Aviel\vsprojects\snookerApp\venv\Lib\site-packages\django\db\models\base.py", line 1161, in _save_table 
    results = self._do_insert(
              ^^^^^^^^^^^^^^^^
  File "C:\Users\Aviel\vsprojects\snookerApp\venv\Lib\site-packages\django\db\models\base.py", line 1202, in _do_insert  
    return manager._insert(
           ^^^^^^^^^^^^^^^^
  File "C:\Users\Aviel\vsprojects\snookerApp\venv\Lib\site-packages\django\db\models\manager.py", line 87, in manager_method
    return getattr(self.get_queryset(), name)(*args, **kwargs)
           ^^^^^^^^^^^^^^^^^^^^^^^^^^^^^^^^^^^^^^^^^^^^^^^^^^^
  File "C:\Users\Aviel\vsprojects\snookerApp\venv\Lib\site-packages\django\db\models\query.py", line 1847, in _insert    
    return query.get_compiler(using=using).execute_sql(returning_fields)
           ^^^^^^^^^^^^^^^^^^^^^^^^^^^^^^^^^^^^^^^^^^^^^^^^^^^^^^^^^^^^^
  File "C:\Users\Aviel\vsprojects\snookerApp\venv\Lib\site-packages\django\db\models\sql\compiler.py", line 1836, in execute_sql
    cursor.execute(sql, params)
  File "C:\Users\Aviel\vsprojects\snookerApp\venv\Lib\site-packages\django\db\backends\utils.py", line 122, in execute   
    return super().execute(sql, params)
           ^^^^^^^^^^^^^^^^^^^^^^^^^^^^
  File "C:\Users\Aviel\vsprojects\snookerApp\venv\Lib\site-packages\django\db\backends\utils.py", line 79, in execute    
    return self._execute_with_wrappers(
           ^^^^^^^^^^^^^^^^^^^^^^^^^^^^
  File "C:\Users\Aviel\vsprojects\snookerApp\venv\Lib\site-packages\django\db\backends\utils.py", line 92, in _execute_with_wrappers
    return executor(sql, params, many, context)
           ^^^^^^^^^^^^^^^^^^^^^^^^^^^^^^^^^^^^
  File "C:\Users\Aviel\vsprojects\snookerApp\venv\Lib\site-packages\django\db\backends\utils.py", line 100, in _execute  
    with self.db.wrap_database_errors:
  File "C:\Users\Aviel\vsprojects\snookerApp\venv\Lib\site-packages\django\db\utils.py", line 91, in __exit__
    raise dj_exc_value.with_traceback(traceback) from exc_value
  File "C:\Users\Aviel\vsprojects\snookerApp\venv\Lib\site-packages\django\db\backends\utils.py", line 105, in _execute  
    return self.cursor.execute(sql, params)
           ^^^^^^^^^^^^^^^^^^^^^^^^^^^^^^^^
django.db.utils.IntegrityError: duplicate key value violates unique constraint "oneFourSeven_ranking_Player_id_Season_Type_cdead264_uniq"
DETAIL:  Key ("Player_id", "Season", "Type")=(12, 2025, MoneyRankings) already exists.


=== UPDATE SUMMARY ===
Total records updated: 0
Duration: 2.43 seconds
Failed to update 1 ranking type(s):
  File "C:\Users\Aviel\vsprojects\snookerApp\venv\Lib\site-packages\django\db\backends\utils.py", line 100, in _execute  
    with self.db.wrap_database_errors:
  File "C:\Users\Aviel\vsprojects\snookerApp\venv\Lib\site-packages\django\db\utils.py", line 91, in __exit__
    raise dj_exc_value.with_traceback(traceback) from exc_value
  File "C:\Users\Aviel\vsprojects\snookerApp\venv\Lib\site-packages\django\db\backends\utils.py", line 105, in _execute  
    return self.cursor.execute(sql, params)
           ^^^^^^^^^^^^^^^^^^^^^^^^^^^^^^^^
django.db.utils.IntegrityError: duplicate key value violates unique constraint "oneFourSeven_ranking_Player_id_Season_Type_cdead264_uniq"
DETAIL:  Key ("Player_id", "Season", "Type")=(12, 2025, MoneyRankings) already exists.


=== UPDATE SUMMARY ===
Total records updated: 0
Duration: 2.43 seconds
Failed to update 1 ranking type(s):
  File "C:\Users\Aviel\vsprojects\snookerApp\venv\Lib\site-packages\django\db\backends\utils.py", line 105, in _execute  
    return self.cursor.execute(sql, params)
           ^^^^^^^^^^^^^^^^^^^^^^^^^^^^^^^^
django.db.utils.IntegrityError: duplicate key value violates unique constraint "oneFourSeven_ranking_Player_id_Season_Type_cdead264_uniq"
DETAIL:  Key ("Player_id", "Season", "Type")=(12, 2025, MoneyRankings) already exists.


=== UPDATE SUMMARY ===
Total records updated: 0
Duration: 2.43 seconds
Failed to update 1 ranking type(s):
DETAIL:  Key ("Player_id", "Season", "Type")=(12, 2025, MoneyRankings) already exists.


=== UPDATE SUMMARY ===
Total records updated: 0
Duration: 2.43 seconds
Failed to update 1 ranking type(s):
  - MoneyRankings
Error updating rankings: No ranking types were updated successfully
Traceback (most recent call last):
  File "C:\Users\Aviel\vsprojects\snookerApp\maxbreak\oneFourSeven\management\commands\update_rankings.py", line 161, in handle
    raise CommandError('No ranking types were updated successfully')
django.core.management.base.CommandError: No ranking types were updated successfully
‚ùå MONTHLY UPDATE FAILED: Rankings update failed: No ranking types were updated successfully